# 47장. 에러처리

프로그램 실행중에 발생한 에러를 방치하면 프로그램이 즉시 종료된다. 이때 예외적인 상황에 대응하기위해 에러처리가 필요하다.  
기본적으로 에러처리를 구현하는 방법은 크게 두가지로 첫번째는 if문이나 단축평가, 옵셔널 체이닝 연산자를 통해 확인하여 처리하는 방법과 `try...catch...finally`문을 통해 처리하는 방법이 있다.

## try...catch 문법

```js
try {
  ... // 실행할 코드 - 에러가 발생할 수 있는 코드
} catch {
  ... // 에러가 발생할 경우 처리할 코드
} finally {
  ... // try..catch 코드블록과 상관없이 반드시 1번 실행할 코드
}
```

#### 동작순서

1. try {...} 코드 블록이 실행된다.
2. 에러가 발생할 경우 에러가 발생한 지점에서 즉시 실행을 멈추고 catch {...} 코드 블록이 실행된다.  
   에러가 없다면 try 마지막 줄 까지 실행되고 catch 블록은 건너뛴다.
3. 전달받은 에러객체를 이용해 catch 블록 안에서 새로운 네트워크 요청을 보내거나 사용자에게 대안을 제안하는 등의 구체적인 작업을 할 수 있다.
4. 마지막 finally {...} 코드블록은 try...catch 문을 빠져나가는 어떤 경우에도 실행된다. (return문을 사용해도 실행됨)

#### try..catch는 동기적으로 동작한다!

```js
// ❌ 비동기로 동작하는 코드는 catch 하지 못함
try {
  setTimeout(() => {
    noSuchVariable;
  }, 1000);
} catch (err) {
  // 에러에 대한 정보가 필요없다면 변수 설정을 생략할 수 있음
  console.err(err);
}
```

```js
setTimeout(() => {
  // ✅ 비동기 동작 코드 내부에 try...catch를 적용해야 에러처리가 가능하다!!!!
  try {
    noSuchVariable;
  } catch (err) {
    console.err(err);
  }
});
```

## Error 객체

> Error 생성자 함수는 에러를 설명하는 에러 메세지를 인수로 전달하여 에러 객체를 생성할 수 있다.
>
> (Error 생성자 함수로 에러 객체를 생성한다고 에러가 발생하는 것은 아님)

Error 생성자 함수에 의해 생성된 에러 객체는 message 프로퍼티, stack 프로퍼티를 갖는다.

- `message property` : 인수로 전달한 에러메세지
- `stack property` : 에러를 발생시킨 콜스택의 호출 정보를 나타내는 문자열 -> 디버깅에 쓰임

```js
new Error('에러에 대한 설명');
```

```js
try {
  // 🌟 에러 객체를 생성한다고 에러가 발생하는 건 아님!
  new Error('something wrong');
} catch (error) {
  console.log(error);
}
```

#### 에러 객체를 생성할 수 있는 7가지 에러 생성자 함수

| 생성자 함수    | 인스턴스                                                                  |
| -------------- | ------------------------------------------------------------------------- |
| Error          | 일반적 에러                                                               |
| SyntaxError    | 문법 에러                                                                 |
| ReferenceError | 참조할 수 없는 식별자 참조했을 때 발생하는 에러                           |
| TypeError      | 피연산자 또는 인수의 데이터 타입이 유효하지 않을 때 발생하는 에러         |
| RangeError     | 숫자값의 허용 범위를 벗어났을 때 발생하는 에러                            |
| URIError       | encodeURI 또는 decodeURI 함수에 부적잘한 인수를 전달했을 때 발생하는 에러 |
| EvalError      | eval 함수에서 발생하는 에러                                               |

## throw 문

> 에러 객체를 지정하여 에러를 발생시키는 문

try 코드블럭에서 에러 객체를 생성하여 던지면 catch 문의 에러 변수로 에러 객체가 할당되면서 코드 블럭이 실행된다.

```js
try {
  // ✅ 에러 객체를 throw로 던져서 에러를 발생시키면 catch 코드블럭이 실행됨!!
  throw new Error('something wrong');
} catch (error) {
  // 🌟 try에서 생성한 에러 객체를 catch 문 에러 변수로 할당받음
  console.log(error);
}
```

```js
let json = '{ "age": 30 }'; // 불완전한 데이터

try {
  let user = JSON.parse(json);

  if (!user.name) { // SyntaxError 발생 (property가 없음)
    throw new SyntaxError('불완전한 데이터: 이름 없음');
  }

  alert(user.name);
} catch (e) {
  alert('JSON Error: ' + e.message); // JSON Error: 불완전한 데이터: 이름 없음
}
```

### 에러 던지기 

알고있는 에러만 처리하고 모르는 에러는 다시 던져서 종류별로 처리할 수 있도록 하는 것이 좋다.

```js
try {

} catch (err) {
  // ✅ 알고있는 Error 에 대해서만 처리하고
  if (err instanceof ReferenceError) {

  } else if (err instanceof SyntaxError) {
    alert( "JSON Error: " + err.message );
  } else throw err;// 🌟 모르는 에러는 다시 던져서 알 수 없는 에러는 건너뛰도록함
  // 호출한 방향으로 던져지고 바깥에 try..catch가 있다면 거기서 에러를 잡는 것임
}
```


## 에러의 전파

에러는 호출자 방향으로 전파된다. 즉, 콜스택의 아래방향으로 전파

```js
const 일 = () => throw Error('1에서 발생한 에러');
const 이 = () => 일();
const 삼 = () => 이();

try {
  삼();
} catch (err) {
  console.error(err);
}
```

<img src="https://github.com/bread1022/TIL/assets/107349637/4ca4a787-46a7-4afa-8037-4852bfe3360f" width="200px"/>

throw Error을 첫번째 함수에서 던졌어도 그 throw된 error를 catch하지 않으면 프로그램은 강제로 종료되기때문에 throw된 에러를 캐치하여 적절히 대응해야 프로그램 강제종료를 방지하고 코드의 실행흐름을 복구할 수 있다.  
이때 주의해야할점, 비동기 함수나 프로미스 후속 처리 메서드의 콜백함수는 호출자가 콜스택에 없기때문에 호출자로 에러가 전파되지 않는다.
